
2022-11-08 17:14:38,109 | ERROR | C:\Users\Alex\edu-dev\news_board_HW_D_13.4 � �����\news\urls.py | None |This is just a test error for now.
2022-11-08 17:17:45,304 | ERROR | C:\Users\Alex\edu-dev\news_board_HW_D_13.4 � �����\news\urls.py | None |This is just a test error for now.
2022-11-08 17:20:18,921 | ERROR | C:\Users\Alex\edu-dev\news_board_HW_D_13.4\news\urls.py | None |This is just a test error for now.
2022-11-08 17:32:07,284 | ERROR | C:\Users\Alex\edu-dev\news_board_HW_D_13.4\news\urls.py | None |This is just a test error for now.
2022-11-08 17:36:28,504 | ERROR | C:\Users\Alex\edu-dev\news_board_HW_D_13.4\news\urls.py | None |This is just a test error for now.
2022-11-08 17:42:21,225 | ERROR | C:\Users\Alex\edu-dev\news_board_HW_D_13.4\news\urls.py | None |This is just a test error for now.
2022-11-08 17:43:57,275 | ERROR | C:\Users\Alex\AppData\Local\Programs\Python\Python39\lib\site-packages\django\utils\log.py | (<class 'django.db.utils.OperationalError'>, OperationalError('database is locked'), <traceback object at 0x0000000006A24500>) |Internal Server Error: /news/5/update/
2022-11-08 17:52:44,501 | ERROR | C:\Users\Alex\AppData\Local\Programs\Python\Python39\lib\site-packages\django\utils\log.py | (<class 'news.models.Author.DoesNotExist'>, DoesNotExist('Author matching query does not exist.'), <traceback object at 0x0000000006B14F00>) |Internal Server Error: /news/create/
Traceback (most recent call last):
  File "C:\Users\Alex\AppData\Local\Programs\Python\Python39\lib\site-packages\django\core\handlers\exception.py", line 55, in inner
    response = get_response(request)
  File "C:\Users\Alex\AppData\Local\Programs\Python\Python39\lib\site-packages\django\core\handlers\base.py", line 197, in _get_response
    response = wrapped_callback(request, *callback_args, **callback_kwargs)
  File "C:\Users\Alex\AppData\Local\Programs\Python\Python39\lib\site-packages\django\views\generic\base.py", line 103, in view
    return self.dispatch(request, *args, **kwargs)
  File "C:\Users\Alex\AppData\Local\Programs\Python\Python39\lib\site-packages\django\contrib\auth\mixins.py", line 109, in dispatch
    return super().dispatch(request, *args, **kwargs)
  File "C:\Users\Alex\AppData\Local\Programs\Python\Python39\lib\site-packages\django\views\generic\base.py", line 142, in dispatch
    return handler(request, *args, **kwargs)
  File "C:\Users\Alex\AppData\Local\Programs\Python\Python39\lib\site-packages\django\views\generic\edit.py", line 184, in post
    return super().post(request, *args, **kwargs)
  File "C:\Users\Alex\AppData\Local\Programs\Python\Python39\lib\site-packages\django\views\generic\edit.py", line 153, in post
    return self.form_valid(form)
  File "C:\Users\Alex\edu-dev\news_board_HW_D_13.4\news\views.py", line 64, in form_valid
    self.object.postAuthor = Author.objects.get(authorUser=self.request.user)
  File "C:\Users\Alex\AppData\Local\Programs\Python\Python39\lib\site-packages\django\db\models\manager.py", line 85, in manager_method
    return getattr(self.get_queryset(), name)(*args, **kwargs)
  File "C:\Users\Alex\AppData\Local\Programs\Python\Python39\lib\site-packages\django\db\models\query.py", line 650, in get
    raise self.model.DoesNotExist(
news.models.Author.DoesNotExist: Author matching query does not exist.
2022-11-08 17:52:44,514 | ERROR | C:\Users\Alex\AppData\Local\Programs\Python\Python39\lib\site-packages\django\core\servers\basehttp.py | None |"POST /news/create/ HTTP/1.1" 500 106942
2022-11-08 17:54:13,544 | ERROR | C:\Users\Alex\edu-dev\news_board_HW_D_13.4\news\urls.py | None |This is just a test error for now.
